fixtures/orders.csv
buy, 1.00000000, 100.00, 2018-08-06T19:26:26+00:00
sell, 1.32350000, 104.00, 2018-08-06T19:27:31+00:00
sell, 4.20000000, 103.50, 2018-08-06T19:30:34+00:00
buy, 2.25000000, 101.00, 2018-08-06T19:33:37+00:00
sell, 5.00000000, 100.75, 2018-08-06T19:35:12+00:00
buy, 3.45000000, 100.55, 2018-08-06T19:40:07+00:00
sell, 2.73400000, 100.45, 2018-08-06T19:45:55+00:00
sell, 2.20000000, 103.50, 2018-08-06T19:48:55+00:00
buy, 0.50000000, 100.75, 2018-08-06T19:48:55+00:00
